Workbook

Sheet Assumptions
A1: Wilson Mining — Pay & Net Income Calculator (Shane Schleger)
A2: Edit yellow cells to model scenarios. Black cells calculate from formulas.
A4: ROLE & ROSTER
A5: Shifts per week | B5: 4 | C5: Mon–Thurs
A6: Hours per shift | B6: 12 | C6: 12-hr night shifts
A7: Total hrs worked / week | B7: =B5*B6 -> 48
A9: PAY RATES (EA cl. 9.2)
A10: Base hourly rate ($/hr) | B10: 37.17 | C10: Experienced Miner, from 1/7/2025
A11: Night shift loading (×) | B11: 1.25 | C11: EA cl. 6.4 — starts after 6pm
A12: Single time hrs per day | B12: 8 | C12: EA cl. 7.1
A13: OT multiplier (× base) | B13: 2 | C13: EA cl. 7.1 — double time after 8/day
A14: Weekly bonus, full ($) | B14: 450 | C14: EA cl. 11.2
A15: Bonus hours cap | B15: 35 | C15: EA cl. 11.1
A17: TRAVEL & ACCOMMODATION (CONFIRMED)
A18: Travel allowance each way ($) | B18: 200 | C18: Cl. 27.1 — own vehicle, out-of-Western district
A19: One-way trips per week | B19: 2 | C19: Mon out, Thu home
A20: Meal allowance per shift ($) | B20: 80 | C20: Cl. 27.3 — self-catered, after-tax basis
A21: Meals claimed per week | B21: 4 | C21: One per shift worked
A23: ANNUAL ASSUMPTIONS
A24: Weeks per year | B24: 52 | C24: Standard
A25: Annual leave weeks | B25: 5 | C25: EA cl. 23 — 25 days/yr
A26: Personal leave days taken | B26: 7 | C26: Editable
A27: Public holidays NOT worked | B27: 6 | C27: Editable
A28: Public holidays worked | B28: 4 | C28: Editable — paid 2× first 8, 3× after
A29: Working weeks per year | B29: 47 | C29: 52 − AL weeks (for travel/meal counts)
A31: TAX (FY 2025-26 resident rates — Stage 3)
A32: Treat meal allowance as LAFHA? (default No) | B32: No | C32: ATO rules suggest you do NOT qualify for LAFHA — see ATO Rules tab

Sheet Weekly
A1: Typical Weekly Pay — 4 × 12 hr Mon–Thurs nights
A3: Wages
A4: Component | B4: Hours | C4: Rate ($/hr) | D4: Amount ($) | E4: Reference
A5: Single time (with 25% night loading) | B5: =Assumptions!B5*Assumptions!B12 -> 32 | C5: =Assumptions!B10*Assumptions!B11 -> 46.4625 | D5: =B5*C5 -> 1486.8 | E5: 32 hrs × $37.17 × 1.25 — first 8 hrs/day
A6: Overtime (double time, no loading) | B6: =Assumptions!B7-B5 -> 16 | C6: =Assumptions!B10*Assumptions!B13 -> 74.34 | D6: =B6*C6 -> 1189.44 | E6: 16 hrs × $37.17 × 2 — hours 9–12 each day
A7: Production bonus | D7: =Assumptions!B14 -> 450 | E7: Cl. 11 — full at 35+ hrs worked
A8: WAGE SUBTOTAL | D8: =SUM(D5:D7) -> 3126.24
A10: Allowances
A11: Travel allowance | B11: =Assumptions!B19 -> 2 | C11: =Assumptions!B18 -> 200 | D11: =B11*C11 -> 400 | E11: 2 one-way trips × $200 — own vehicle, out-of-district
A12: Meal allowance | B12: =Assumptions!B21 -> 4 | C12: =Assumptions!B20 -> 80 | D12: =B12*C12 -> 320 | E12: 4 shifts × $80 — self-catered
A13: ALLOWANCE SUBTOTAL | D13: =SUM(D11:D12) -> 720
A15: WEEKLY GROSS TOTAL | D15: =D8+D13 -> 3846.24
A17: Note: Wage subtotal alone = $3,126/wk. With allowances = $3,846/wk. OT clause interpretation (cl. 7.1 vs 7.8) is ambiguous — confirm with Wilson payroll.

Sheet Other Week Types
A1: Other Pay Scenarios
A3: Annual Leave Week
A4: Hours paid (5 × 8) | B4: 40 | C4: =Assumptions!B10*1.25 -> 46.4625 | D4: =B4*C4 -> 1858.5 | E4: Cl. 23.6 — 25% leave loading
A5: Bonus on AL | D5: =Assumptions!B14 -> 450 | E5: Cl. 23.6 — bonus paid during AL
A6: AL WEEK TOTAL | D6: =D4+D5 -> 2308.5
A8: Public Holiday Worked (12 hr night shift)
A9: First 8 hrs @ 2× base | B9: 8 | C9: =Assumptions!B10*2 -> 74.34 | D9: =B9*C9 -> 594.72 | E9: Cl. 22.2
A10: Hours 9–12 @ 3× base | B10: 4 | C10: =Assumptions!B10*3 -> 111.51 | D10: =B10*C10 -> 446.04 | E10: Cl. 22.2
A11: PH SHIFT TOTAL | D11: =SUM(D9:D10) -> 1040.76

Sheet Annual
A1: Annual Income (Gross)
A3: Item | B3: Qty | C3: Amount ($) | D3: Notes
A4: WAGES
A5: Standard working weeks | B5: =Assumptions!B29 -> 47 | C5: =B5*Weekly!D8 -> 146933.28 | D5: Wage subtotal × working weeks
A6: Annual leave weeks | B6: =Assumptions!B25 -> 5 | C6: =B6*'Other Week Types'!D6 -> 11542.5 | D6: Cl. 23.6 — base × 1.25 + bonus
A7: Less: personal leave days taken | B7: =Assumptions!B26 -> 7 | C7: =-B7*((Assumptions!B12*Assumptions!B10*Assumptions!B11+(Assumptions!B6-Assumptions!B12)*Assumptions!B10*Assumptions!B13)-(8*Assumptions!B10)) -> -2601.9 | D7: Net: PL day replaces a working shift
A8: Public holidays NOT worked | B8: =Assumptions!B27 -> 6 | C8: =B8*8*Assumptions!B10 -> 1784.16 | D8: Cl. 22.2
A9: Public holidays WORKED | B9: =Assumptions!B28 -> 4 | C9: =B9*'Other Week Types'!D11 -> 4163.04 | D9: Cl. 22.2 — 2× then 3×
A10: ANNUAL WAGES (taxable income) | C10: =SUM(C5:C9) -> 161821.08
A12: ALLOWANCES
A13: Travel allowance | B13: =Assumptions!B29*Assumptions!B19 -> 94 | C13: =B13*Assumptions!B18 -> 18800 | D13: 47 wks × 2 trips × $200
A14: Meal allowance | B14: =Assumptions!B29*Assumptions!B21 -> 188 | C14: =B14*Assumptions!B20 -> 15040 | D14: 47 wks × 4 shifts × $80
A15: ANNUAL ALLOWANCES | C15: =SUM(C13:C14) -> 33840
A17: TOTAL ANNUAL GROSS (no super) | C17: =C10+C15 -> 195661.08

Sheet Tax & Net
A1: Tax Estimate & Net Income (FY 2025-26)
A2: Australian resident rates — Stage 3 tax cuts in effect from 1/7/2024.
A4: FY 2025-26 Resident Tax Brackets
A5: Bracket | B5: Threshold ($) | C5: Rate | D5: Notes
A6: 1 — Tax-free | B6: 0 | C6: 0 | D6: Up to $18,200
A7: 2 | B7: 18200 | C7: 0.16 | D7: $18,201 – $45,000
A8: 3 | B8: 45000 | C8: 0.3 | D8: $45,001 – $135,000
A9: 4 | B9: 135000 | C9: 0.37 | D9: $135,001 – $190,000
A10: 5 | B10: 190000 | C10: 0.45 | D10: Above $190,000
A11: Medicare levy | C11: 0.02 | D11: 2% on taxable income (assumes no MLS — verify with private health cover)
A13: Net Income Calculation
A14: Annual wages | C14: =Annual!C10 -> 161821.08 | D14: Fully taxable
A15: Travel allowance | C15: =Annual!C13 -> 18800 | D15: Treated as taxable (conservative — see notes)
A16: Meal allowance | C16: =Annual!C14 -> 15040 | D16: Treated per LAFHA toggle (Assumptions tab)
A17: TAXABLE INCOME | C17: =IF(Assumptions!B32="Yes", C14+C15, C14+C15+C16) -> 195661.08 | D17: If meal is LAFHA, subtract from taxable
A19: Income tax — step by step
A20: $0 – $18,200 @ 0% | C20: =0 -> 0 | D20: Tax-free threshold
A21: $18,201 – $45,000 @ 16% | C21: =MAX(0, MIN(C17,45000)-18200)*0.16 -> 4288 | D21: Up to $4,288
A22: $45,001 – $135,000 @ 30% | C22: =MAX(0, MIN(C17,135000)-45000)*0.3 -> 27000 | D22: Up to $27,000
A23: $135,001 – $190,000 @ 37% | C23: =MAX(0, MIN(C17,190000)-135000)*0.37 -> 20350 | D23: Up to $20,350
A24: Above $190,000 @ 45% | C24: =MAX(0, C17-190000)*0.45 -> 2547.486 | D24: On excess
A25: Income tax subtotal | C25: =SUM(C20:C24) -> 54185.486
A26: Medicare levy (2%) | C26: =C17*0.02 -> 3913.2216
A27: TOTAL TAX & LEVY | C27: =C25+C26 -> 58098.708
A29: ANNUAL NET INCOME | C29: =IF(Assumptions!B32="Yes", C17-C27+C16, C14+C15+C16-C27) -> 137562.37 | D29: Take-home (after tax + levy). If LAFHA, meal allowance added back.
A30: Approx weekly net (÷52) | C30: =C29/52 -> 2645.4302 | D30: Crude weekly average — actual varies by AL/PH
A31: Effective tax rate | C31: =C27/(C14+C15+C16) -> 0.29693543 | D31: Total tax ÷ total cash received
A33: Caveats & assumptions
A34: 1. Tax brackets are FY2025-26 (Stage 3 cuts). FY26-27 rates not yet legislated changes assumed identical.
A35: 2. Medicare levy assumes you're above the threshold ($30k+) and don't qualify for reduction. No MLS assumed (have private hospital cover).
A36: 3. Travel allowance taxed conservatively. In practice, bona fide travel allowances paid at ATO 'reasonable amounts' may be paid without PAYG withholding, and you may claim car expenses as a deduction — this would reduce your actual tax bill. Talk to an accountant.
A37: 4. Meal allowance: EA says '$80 after tax'. If treated as taxable income, it's in your gross. If treated as LAFHA / reasonable amount (toggle on Assumptions tab), it's tax-free up to ATO thresholds.
A38: 5. No HELP/HECS debt assumed. No salary sacrifice assumed. No private health offset/rebate modelled.
A39: 6. Super excluded from total per Shane's request — it's earned but not part of take-home.
A40: 7. This is an estimate, not financial advice. Get a tax accountant to confirm — even a single session before signing is cheap insurance.

Sheet ATO Rules
A1: ATO Rules — Travel, Meal Allowances, LAFHA, Deductions
A2: Research conducted May 2026. Confirm with a registered tax agent before lodging.
A5: ✕ | B5: The ATO position (TR 2021/1, TR 2021/4) is clear: a regular mine site IS your workplace, even if you sleep there. Travel between your home and that mine site is treated as ORDINARY COMMUTING — not deductible.
A6: ✕ | B6: This holds even if your employer pays a 'travel allowance' for the trip. Receiving the allowance doesn't make the underlying expense deductible.
A7: ! | B7: The TR 2021/4 ruling includes a literal example of a worker at the Olympic Dam mine in SA — exactly your scenario. ATO treats his allowance as a LAFHA, not as 'travel'.
A8: ✕ | B8: LAFHA also doesn't usually apply to roster-based DIDO arrangements where the worker stays in employer-provided camp accommodation. The worker isn't 'establishing a second home' — they're commuting on a longer cycle.
A11: ✕ | B11: Travel allowance ($18,800/yr): TAXABLE income in full. It will appear on your PAYG payment summary as 'allowances'. You cannot claim car expenses against it for the Sydney↔Ulan trip — that's commuting (per TR 2021/1).
A12: ✕ | B12: Meal allowance ($15,040/yr): TAXABLE income in full IF it appears on your PAYG summary. There's a narrow exception (overtime meal allowance) — see below.
A13: ! | B13: The EA's phrase '$80 per day after tax' is unusual. Possible interpretations: (1) employer grosses it up so you net $80, (2) employer treats as FBT-exempt fringe benefit and pays $80 cash. CHECK YOUR FIRST PAYSLIP to see how Wilson actually treats it.
A14: ✓ | B14: If Wilson treats either allowance as a fringe benefit (FBT) and it does NOT appear on your PAYG summary, it's effectively tax-free to you. This is the best outcome and the EA wording hints at this for meals.
B17: Under TD 2025/4, employees who receive an overtime meal allowance under an industrial instrument can claim up to $38.65 per overtime meal without receipts (the 'reasonable amount'). To qualify:
A18: ✓ | B18: Shift must exceed normal hours (your 12-hour nights satisfy this — EA cl. 7 treats hours over 8/day as overtime)
A19: ! | B19: The allowance must be paid under an award/EA specifically in connection with overtime — NOT for being away from home
A20: ! | B20: You must actually incur a meal expense (i.e. you bought food). If the camp is fully catered and meals are free, you can't claim.
A21: ! | B21: Your EA's $80/day meal allowance is described as accommodation-related (cl. 27.3), not overtime-related. Get a tax agent to assess whether it can be characterised as overtime meal allowance for ATO purposes. If yes, you may be able to claim up to $38.65 per shift × 188 shifts = $7,266/yr without receipts.
A24: ✕ | B24: Sydney → Ulan trip (~280 km each way): NOT DEDUCTIBLE under TR 2021/1, regardless of how you travel or who pays.
A25: ! | B25: Cents-per-km method 2025-26: 88c/km, capped at 5,000 work-km/yr (~$4,400 max). Does NOT apply to home-to-work commute.
A26: ! | B26: Logbook method: requires 12 consecutive weeks of records. Validates business-use % for 5 years. Only applies to genuinely work-related km.
A27: ✓ | B27: What MIGHT be deductible: travel between two different mine sites in a single day; emergency callouts to a non-regular site (cl. 27); travel for training/courses; travel between mine and another work location.
A28: ✓ | B28: Keep a logbook from day 1 — even if you think most use is commuting. You'll be surprised what qualifies and the cost of starting late is high.
A31: ✓ | B31: MEU (Mining & Energy Union) membership fees — fully deductible
A32: ✓ | B32: Income protection insurance premiums (NOT life insurance, NOT inside-super premiums)
A33: ✓ | B33: Sun protection (sunscreen, sunglasses, hats) IF working outdoors/in sun
... A59: • | B59: ATO Mining site employees guide (May 2025): ato.gov.au/mining

Sheet Logs to Keep
A1: Logs & Records to Keep from Day 1 (2 June 2026)
B3: VEHICLE LOGBOOK — start day 1
A4: ☐ | B4: 12-week logbook (consecutive) | C4: Start 2 June 2026. Continuous for 12 weeks. Each trip: date, start/end odometer, km, purpose. Required for ATO logbook method. Valid 5 years once done.
A5: ☐ | B5: Odometer reading at 1 July each year | C5: Photo of odometer on 1 July 2026 and 30 June 2027. Annual records support business-use % across the year.
A6: ☐ | B6: Car details | C6: Make, model, engine capacity, rego number — once in the logbook.
A7: ☐ | B7: Receipts for car running costs | C7: Fuel, servicing, insurance, registration, tyres, repairs. Keep ALL receipts even if Sydney→Ulan trips aren't deductible — some km may be (training, between sites, callouts).
B8: WORK DIARY (calendar entries are fine)
A9: ☐ | B9: Shift dates, hours, location | C9: Every shift: date, start/end times, location (Ulan or other), 12-hr night confirmed. Supports overtime meal allowance claims and OT calculations.
A10: ☐ | B10: Out-of-pocket meal expenses | C10: Date, location, amount, what (breakfast/lunch/dinner). Keep receipts where possible. Critical for overtime meal allowance claim defence.
A11: ☐ | B11: Travel between sites | C11: Any trip between Ulan and another work location, training venue, or callout site. Date, from→to, km, purpose. These ARE potentially deductible.
A12: ☐ | B12: Training / courses attended | C12: Date, course name, cost, location, employer reimbursement status.
B13: PAYSLIPS & PAYG
A14: ☐ | B14: Every payslip retained | C14: From first pay. Shows allowance breakdowns (travel, meal, bonus), tax withheld, super, hours worked. Lose nothing.
A15: ☐ | B15: Annual PAYG payment summary | C15: End of FY. Confirms how Wilson treated each allowance for tax. CRITICAL — this is the evidence for what's taxable.
A16: ☐ | B16: Write-down of allowance treatment | C16: On your first payslip, confirm in writing with payroll: which allowances are on PAYG summary (taxable) vs. FBT-treated (excluded). Keep that email.
B17: RECEIPTS — KEEP EVERYTHING WORK-RELATED
A18: ☐ | B18: Union fees (MEU) | C18: Annual or fortnightly deductions — keep statement or union letter.
A19: ☐ | B19: Income protection insurance | C19: Premium notice/policy schedule. NOT life insurance and NOT premiums paid inside super (which aren't deductible).
A20: ☐ | B20: PPE you buy yourself | C20: Beyond what Wilson provides — e.g. extra boots, safety glasses, gloves, additional clothing. Receipts dated and itemised.
A21: ☐ | B21: Sun protection | C21: Sunglasses, sunscreen, broad-brim hat if working outdoors. Receipts.
A22: ☐ | B22: Tools & equipment | C22: Tools you buy for the role. Items >$300 may need depreciation.
A23: ☐ | B23: Phone & internet | C23: Monthly bills + a 4-week diary period showing work vs personal use to establish %.
A24: ☐ | B24: Tax agent fees | C24: Invoice from accountant. Yes, this is deductible.
A25: ☐ | B25: Industry publications | C25: Subscriptions, technical books, training materials.
B26: EMPLOYMENT DOCUMENTS — file these for life-of-contract
A27: ☐ | B27: Offer letter + EA | C27: You have these — keep originals.
A28: ☐ | B28: Written confirmation from Wilson on: | C28: Home district designation; accommodation type (catered/self-catered); travel arrangement; whether allowances are PAYG or FBT.
A29: ☐ | B29: Roster confirmations | C29: Each rostered period — keep emails/SMS so you can prove shift patterns if disputed later.
B30: ATO-APPROVED TOOLS
A31: ☐ | B31: ATO myDeductions app | C31: Free, official, captures receipts via phone camera + categorises. Syncs to MyTax at lodgment. Use from day 1.
A32: ☐ | B32: Logbook app (e.g. Driversnote, GOFAR) | C32: Auto-trip detection. Reduces tedium. Saves time at tax lodgment.

Sheet PHI vs MLS
A1: Private Health Insurance vs Medicare Levy Surcharge — Single, NSW
A2: Estimated annual costs assuming you're under 65, no LHC loading, $750 excess, Tier 3 income (no rebate). Real quotes vary — use privatehealth.gov.au.
A4: Your Situation
A5: Annual taxable income (from Tax & Net) | B5: ='Tax & Net'!C17 -> 195661.08 | F5: Used to compute MLS
A6: MLS Tier | B6: =IF(B5<=101000,"Tier 0",IF(B5<=118000,"Tier 1",IF(B5<=158000,"Tier 2","Tier 3"))) -> Tier 3 | F6: Based on 2025-26 single thresholds
A7: MLS rate | B7: =IF(B5<=101000,0,IF(B5<=118000,0.01,IF(B5<=158000,0.0125,0.015))) -> 0.015 | F7: Tier 3 (>$158k) = 1.5% — your bracket
A8: MLS payable if NO qualifying cover | B8: =B5*B7 -> 2934.9162 | F8: The 'do nothing' tax cost
A9: PHI Rebate eligibility | B9: =IF(B5<=151000, "Rebate applies", "0% rebate (Tier 3)") -> 0% rebate (Tier 3) | F9: At your income, advertised prices grossed up
A11: Comparison — Single, NSW, no rebate, $750 excess
A12: Option | B12: Premium ($/yr) | C12: MLS ($/yr) | D12: Total cost ($/yr) | E12: vs MLS only | F12: What you get
A13: Do nothing (no PHI) | B13: 0 | C13: =IF(B13=0, B$8, 0) -> 2934.9162 | D13: =B13+C13 -> 2934.9162 | E13: =D13-B$8 -> 0 | F13: Nothing. Public hospital waitlist only. No choice of doctor.
A14: Basic Hospital (cheapest qualifying) | B14: 1450 | C14: =IF(B14=0, B$8, 0) -> 0 | D14: =B14+C14 -> 1450 | E14: =D14-B$8 -> -1484.9162 | F14: Avoids MLS only. Excludes joints, heart, back/neck — covers little useful.
A15: Bronze Hospital | B15: 1900 | C15: =IF(B15=0, B$8, 0) -> 0 | D15: =B15+C15 -> 1900 | E15: =D15-B$8 -> -1034.9162 | F15: Joint reconstructions, hernia/appendix, gallbladder, gynae. No back/neck.
A16: Bronze Plus | B16: 2300 | C16: =IF(B16=0, B$8, 0) -> 0 | D16: =B16+C16 -> 2300 | E16: =D16-B$8 -> -634.9162 | F16: Bronze + dental surgery, prostate. Still no back/neck or joint replacement.
A17: Silver Hospital | B17: 3000 | C17: =IF(B17=0, B$8, 0) -> 0 | D17: =B17+C17 -> 3000 | E17: =D17-B$8 -> 65.0838 | F17: Bronze + back/neck/spine, heart, lung, chest. RELEVANT for mining work.
A18: Silver Plus | B18: 3400 | C18: =IF(B18=0, B$8, 0) -> 0 | D18: =B18+C18 -> 3400 | E18: =D18-B$8 -> 465.0838 | F18: Silver + joint replacements, cataracts, sleep studies. Strongly recommended.
A19: Gold Hospital | B19: 4800 | C19: =IF(B19=0, B$8, 0) -> 0 | D19: =B19+C19 -> 4800 | E19: =D19-B$8 -> 1865.0838 | F19: Everything — incl. pregnancy/birth, IVF, weight-loss, psychiatric, hip & knee. Only if you need it.
A20: Note: Premiums are realistic mid-range estimates for a 30-50yo NSW single, no LHC loading, Tier 3 (no rebate).
A22: Specific Silver / Silver Plus Policies to Get Quotes On
A23: Insurer | B23: Policy name (typical) | F23: Notes
A24: HCF | B24: Hospital Standard Silver Plus | F24: Member-owned, not-for-profit. Highly Commended in CHOICE 2025 Silver category.
A25: Bupa | B25: Silver Plus Intermediate / Advanced | F25: Largest network of agreement hospitals. Highly Commended in CHOICE 2025.
A26: Medibank | B26: Silver Plus Core / Secure | F26: Largest membership base. Owns AHM (cheaper sub-brand).
A27: AHM (Medibank sub) | B27: Core Silver Plus | F27: Often cheaper than parent Medibank for same cover.
A28: NIB | B28: Top Hospital (Silver Plus equivalent) | F28: Strong in NSW. Mining workforce common customer.
A29: HBF | B29: Silver Hospital Plus | F29: Strong on gap protection.
A30: Peoplecare | B30: Silver Plus Essentials | F30: Member-owned mutual fund.
A31: GMHBA | B31: Silver Plus Hospital | F31: Regional fund, competitive pricing.
A33: Get Quotes — Use this checklist
A34: 1. | B34: Go to privatehealth.gov.au (free, no commissions). Filter Silver Plus, NSW, single, $750 excess.
A35: 2. | B35: Note your AGE — affects LHC loading. Born after 1 July 1994 + first PHI now = 0% loading (free). Older = 2% per year delayed since age 31.
A36: 3. | B36: Confirm Tier 3 (no rebate) — at your income the advertised 'with rebate' prices need grossing up by ~32%.
A37: 4. | B37: Check back/neck/spine, joint replacement, plastic & reconstructive after injury are FULLY covered (not 'restricted').
A38: 5. | B38: Verify $750 excess (or lower) — must be ≤$750 to keep MLS exemption.
A39: 6. | B39: Ambulance cover — NSW residents need to buy this separately (or via PHI). NSW does NOT have universal ambulance like QLD/TAS.
A40: 7. | B40: Get quotes from at least 3 funds. Same tier, same excess, same exclusions — let price decide.
A41: 8. | B41: Decide on extras separately. Pure hospital cover is what gives you the MLS exemption.
A42: 9. | B42: Take out cover BEFORE you start the role (or in your first month) to avoid any pro-rata MLS for uncovered days.
A44: Key Push-Backs
A45: • | B45: Don't buy Basic 'MLS dodge' policies if your work has physical injury risk. You're paying ~$1,450/yr for cover that won't help when you need it.
...
